Workbook

Sheet Assumptions
A1: Iowa City Community School District
A2: FY2027 Consolidated Cashflow Model — Assumptions & Inputs
A3: All blue cells are inputs. Black = formulas. Green = links from other tabs.
A5: 1. FY2026 ENDING / FY2027 OPENING CASH BALANCES
A6: Fund | B6: 7/1/2026 Cash | C6: Source
A7: General Fund | B7: ='GF Monthly FY26'!M22 -> 26311953 | C7: PFM Aug 11, 2026 — Exhibit 2
A8: SAVE (Statewide Sales & Services Tax) | B8: -1788950 | C8: PFM Jun 9, 2026 — SAVE Exhibit 1
A9: PPEL (Physical Plant & Equipment Levy) | B9: 4580307 | C9: PFM Jun 9, 2026 — PPEL Exhibit 1a
A10: Total modeled funds | B10: =SUM(B7:B9) -> 29103310
A12: 2. ANTICIPATORY WARRANT (TAXABLE, DRAW-DOWN)
A13: Scenario toggle (1 = issue warrant, 0 = no warrant) | B13: 0 | C13: <- change to 0 to see the no-warrant base case
A14: Authorized not-to-exceed amount | B14: 8000000 | C14: PFM Aug 11, 2026 recommendation
A15: Assumed taxable interest rate (annual, on drawn balance) | B15: 0.06 | C15: Estimate — PFM notes no interest cost unless borrowed
A16: Minimum General Fund cash floor (triggers a draw) | B16: 8000000 | C16: Approx. 2 weeks of payroll + benefits
A17: Cash above this level is swept to repay outstanding draws | B17: 15000000 | C17: Repayment sweep threshold
A18: Draw rounding increment | B18: 100000
A19: First month a draw is permitted | B19: 46266 | C19: Closing targeted Sept 11, prior to Sept 15 payroll
A20: Warrant must be fully repaid by | B20: 46539
A22: 3. INTERFUND LOAN TERMS
A23: Insurance Fund loan to General Fund — principal | B23: 10000000 | C23: Drawn Aug-25; legally due no later than Sept 1, 2026
A24: Insurance Fund loan — repayment incl. interest | B24: 10600000 | C24: $600,000 of interest
A25: General Fund loan to SAVE (May-26) — principal | B25: 7320000 | C25: Funded to make June 1, 2026 SAVE debt service
A26: SAVE repayment to General Fund incl. interest | B26: 7759200 | C26: $439,200 of interest = 6.0%
A27: New GF loan to SAVE for June 1, 2027 debt service | B27: 6100000 | C27: Per Aug 11 deck — NOT in PFM's Exhibit 2
A28: Third GF loan to SAVE for June 1, 2028 debt service | C28: Per Aug 11 deck — NOT in PFM's Exhibit 2
A29: Unidentified repayment out, Nov-26 (per Exhibit 2) | B29: 2500000 | C29: Counterparty not identified in PFM materials
A30: GF payable to SAVE per FY2024 audit (unscheduled) | B30: 4000000 | C30: Excluded from cashflow — timing unknown
A31: GF payable to PPEL per FY2024 audit (unscheduled) | B31: 3000000 | C31: Excluded from cashflow — timing unknown
A33: 4. OTHER MODEL INPUTS
A34: Include the two new May-27 SAVE loans in GF cashflow? (1/0) | B34: 1 | C34: 0 reproduces PFM's Aug 11 Exhibit 2 exactly
A35: Interest rate charged on new GF loans to SAVE | B35: =B26/B25-1 -> 0.06 | C35: Implied from the $7,320,000 / $7,759,200 loan
A36: Days cash on hand — daily expenditure basis | B36: =-'GF Monthly FY27'!N19/365 -> 676458.89 | C36: Total FY27 GF expenditures / 365
A38: 5. RECONCILIATION OF SOURCE DOCUMENTS
A39: Document | B39: Date | C39: Role in this model
A40: PFM — GF Monthly Cashflow Update & Warrant Recommendation | B40: 46245 | C40: PRIMARY — GF FY27 monthly operating lines and FY26 actual ending cash
A41: PFM — Capital Funding Capacity: SAVE & PPEL Analyses | B41: 46182 | C41: PRIMARY — SAVE and PPEL FY27 revenue, debt service and capital outlay
A42: PFM — YTD GF Fiscal Progress & Need to Issue Warrants | B42: 46140 | C42: SUPERSEDED — retained only as a variance benchmark
A43: Independent Auditor's Report, FY ended June 30, 2024 | B43: FY2024 | C43: Interfund receivable/payable balances and Finding 2024-008

Sheet Interfund Matrix
A1: Interfund Transfer Matrix — FY2027
A2: Every interfund flow is entered ONCE here. Each fund tab pulls its inflows and outflows from this table, so every transfer is booked exactly twice and the system nets to zero.
A4: # | B4: Description | C4: Paying Fund | D4: Receiving Fund | E4: Month | F4: Gross Amount | G4: Incl. | H4: Modeled Amount | I4: Type | J4: Source / Note
A5: 1 | B5: Repay Self-Insurance Fund interfund loan (incl. $600k interest) | C5: General Fund | D5: Insurance | E5: 46266 | F5: =Assumptions!B24 -> 10600000 | G5: 1 | H5: =F5*G5 -> 10600000 | I5: Loan repayment OUT | J5: PFM Aug 11, 2026 — Exhibit 2 & Interfund Loans Update
A6: 2 | B6: SAVE repays General Fund interfund loan (incl. $439k interest) | C6: SAVE | D6: General Fund | E6: 46266 | F6: =Assumptions!B26 -> 7759200 | G6: 1 | H6: =F6*G6 -> 7759200 | I6: Loan repayment IN | J6: PFM Aug 11, 2026 — Exhibit 2 & SAVE Exhibit 1 (FY27 transfers out)
A7: 3 | B7: Loan repayment out — counterparty fund not identified by PFM | C7: General Fund | D7: Unidentified | E7: 46327 | F7: =Assumptions!B29 -> 2500000 | G7: 1 | H7: =F7*G7 -> 2500000 | I7: Loan repayment OUT | J7: PFM Aug 11, 2026 — Exhibit 2, Nov-26. OPEN ITEM: confirm counterparty
A8: 4 | B8: New GF interfund loan to SAVE for June 1, 2027 debt service | C8: General Fund | D8: SAVE | E8: 46508 | F8: =Assumptions!B27 -> 6100000 | G8: =Assumptions!B34 -> 1 | H8: =F8*G8 -> 6100000 | I8: New loan OUT | J8: PFM Aug 11, 2026 — narrative only; NOT in PFM's Exhibit 2
A9: 5 | B9: Third GF interfund loan to SAVE for June 1, 2028 debt service | C9: General Fund | D9: SAVE | E9: 46508 | F9: =Assumptions!B28 -> 0 | G9: =Assumptions!B34 -> 1 | H9: =F9*G9 -> 0 | I9: New loan OUT | J9: PFM Aug 11, 2026 — narrative only; NOT in PFM's Exhibit 2
A10: 6 | B10: MEMO: GF payable to SAVE per FY2024 audit — timing unknown | C10: General Fund | D10: SAVE | E10: n/a | F10: =Assumptions!B30 -> 4000000 | G10: 0 | H10: =F10*G10 -> 0 | I10: Unscheduled payable | J10: PFM Aug 11, 2026 — excluded pending FY2025 audit
A11: 7 | B11: MEMO: GF payable to PPEL per FY2024 audit — timing unknown | C11: General Fund | D11: PPEL | E11: n/a | F11: =Assumptions!B31 -> 3000000 | G11: 0 | H11: =F11*G11 -> 0 | I11: Unscheduled payable | J11: PFM Aug 11, 2026 — excluded pending FY2025 audit
B12: Total modeled interfund flows | F12: =SUM(F5:F11) -> 33959200 | H12: =SUM(H5:H11) -> 26959200

Sheet GF Monthly FY26
A1: Iowa City Community School District
A2: General Fund Monthly Cashflow
A3: FY 2025-26 — Actual / Estimated (PFM Exhibit 1, August 11, 2026) | N3: FY2026 Total
B4: 45839 | C4: 45870 | D4: 45901 | E4: 45931 | F4: 45962 | G4: 45992 | H4: 46023 | I4: 46054 | J4: 46082 | K4: 46113 | L4: 46143 | M4: 46174
A5: Opening Cash Position | B5: 19364761 | C5: =B22 -> 9436503 | D5: =C22 -> 6020237 | E5: =D22 -> 5116615 | F5: =E22 -> 34015535 | G5: =F22 -> 31758319 | H5: =G22 -> 26378299 | I5: =H22 -> 19599245 | J5: =I22 -> 16159304 | ... M5: =L22 -> 30005421 | N5: =B5 -> 19364761
A7: State Aid | B7: 423804 | C7: 0 | D7: 10648629 | E7: 10649513 | F7: 10649071 | G7: 10649071 | H7: 10593772 | I7: 10593772 | J7: 10593772 | K7: 10593772 | L7: 10593772 | M7: 10593772 | N7: =SUM(B7:M7) -> 106582720
A8: Local Taxes | B8: 379454 | C8: 1067 | D8: 6213734 | E8: 33780407 | F8: 5229494 | G8: 1330659 | H8: 814914 | I8: 361885 | J8: 3114234 | K8: 30156381 | L8: 4538720.1 | M8: 885844.25 | N8: =SUM(B8:M8) -> 86806794
A9: Other GF Revenues | B9: 707917 | C9: 941910 | D9: 4053518 | E9: 3490933 | F9: 272031 | G9: 221773 | H9: 941453 | I9: 4173236 | J9: 2496828 | K9: 1803913.6 | L9: 3129516.8 | M9: 7433345.8 | N9: =SUM(B9:M9) -> 29666375
A10: GF Warrant Proceeds | B10: 0 | C10: 0 | D10: 0 | E10: 0 | F10: 0 | G10: 0 | H10: 0 | I10: 0 | J10: 0 | K10: 0 | L10: 0 | M10: 0 | N10: =SUM(B10:M10) -> 0
A11: Loan Repayments IN | B11: 0 | C11: 10000000 | D11: 0 | E11: 0 | F11: 0 | G11: 0 | H11: 0 | I11: 0 | J11: 0 | K11: 0 | L11: 0 | M11: 0 | N11: =SUM(B11:M11) -> 10000000
A12: Total Income | B12: =SUM(B7:B11) -> 1511175 | C12: =SUM(C7:C11) -> 10942977 | D12: =SUM(D7:D11) -> 20915881 | E12: =SUM(E7:E11) -> 47920853 | F12: =SUM(F7:F11) -> 16150596 | G12: =SUM(G7:G11) -> 12201503 | H12: =SUM(H7:H11) -> 12350139 | I12: =SUM(I7:I11) -> 15128893 | ... M12: =SUM(M7:M11) -> 18912962 | N12: =SUM(B12:M12) -> 2.3305589e+08
A14: Payroll & Benefits | B14: -11590643 | C14: -11885147 | D14: -15886172 | E14: -16354879 | F14: -16377911 | G14: -16134172 | H14: -15608001 | I14: -16350451 | J14: -15882730 | K14: -15767833 | L14: -16610155 | M14: -18860380 | N14: =SUM(B14:M14) -> -187308474
A15: Other General Expenses | B15: 151210 | C15: -2474096 | D15: -5933331 | E15: -2667054 | F15: -2029901 | G15: -1447351 | H15: -3521192 | I15: -2218383 | J15: -1998467 | K15: -1987096 | L15: -2329321 | M15: -3746050 | N15: =SUM(B15:M15) -> -30201032
A16: ERate Refunding to SAVE | B16: 0 | C16: 0 | D16: 0 | E16: 0 | F16: 0 | G16: 0 | H16: 0 | I16: 0 | J16: 0 | K16: -20000 | L16: 0 | M16: 0 | N16: =SUM(B16:M16) -> -20000
A17: Interfund Loans Out | B17: 0 | C17: 0 | D17: 0 | E17: 0 | F17: 0 | G17: 0 | H17: 0 | I17: 0 | J17: 0 | K17: 0 | L17: -8579191 | M17: 0 | N17: =SUM(B17:M17) -> -8579191
A18: Loan Repayments OUT | B18: 0 | C18: 0 | D18: 0 | E18: 0 | F18: 0 | G18: 0 | H18: 0 | I18: 0 | J18: 0 | K18: 0 | L18: 0 | M18: 0 | N18: =SUM(B18:M18) -> 0
A19: Total Expenses | B19: =SUM(B14:B18) -> -11439433 | C19: =SUM(C14:C18) -> -14359243 | D19: =SUM(D14:D18) -> -21819503 | E19: =SUM(E14:E18) -> -19021933 | F19: =SUM(F14:F18) -> -18407812 | G19: =SUM(G14:G18) -> -17581523 | H19: =SUM(H14:H18) -> -19129193 | I19: =SUM(I14:I18) -> -18568834 | ... M19: =SUM(M14:M18) -> -22606430 | N19: =SUM(B19:M19) -> -226108697
A21: Net Change In position | B21: =B12+B19 -> -9928258 | C21: =C12+C19 -> -3416266 | D21: =D12+D19 -> -903622 | E21: =E12+E19 -> 28898920 | F21: =F12+F19 -> -2257216 | G21: =G12+G19 -> -5380020 | H21: =H12+H19 -> -6779054 | I21: =I12+I19 -> -3439941 | ... M21: =M12+M19 -> -3693468 | N21: =SUM(B21:M21) -> 6947191.8
A22: Ending Cash Position | B22: =B5+B21 -> 9436503 | C22: =C5+C21 -> 6020237 | D22: =D5+D21 -> 5116615 | E22: =E5+E21 -> 34015535 | F22: =F5+F21 -> 31758319 | G22: =G5+G21 -> 26378299 | H22: =H5+H21 -> 19599245 | I22: =I5+I21 -> 16159304 | ... M22: =M5+M21 -> 26311953 | N22: =M22 -> 26311953
A24: CHECK — vs PFM Exhibit 1 published ending balances
A25: PFM published | B25: 9436504 | C25: 6020238 | D25: 5116615 | E25: 34015535 | F25: 31758319 | G25: 26378299 | H25: 19599245 | I25: 16159305 | J25: 14482941 | K25: 39262079 | L25: 30005421 | M25: 26311953
A26: Variance (rounding) | B26: =B22-B25 -> -1 | C26: =C22-C25 -> -1 | D26: =D22-D25 -> 0 | E26: =E22-E25 -> 0 | F26: =F22-F25 -> 0 | G26: =G22-G25 -> 0 | H26: =H22-H25 -> 0 | I26: =I22-I25 -> -1 | ... M26: =M22-M25 -> -0.16
A28: FY2026 net variance vs PFM's April 28 projection (per Aug 11 slide 4)
A29: Revenue variance | B29: -649862
A30: Expenditure variance | B30: 5602301
A31: Net positive variance | B31: =B29+B30 -> 4952439 | C31: vs PFM stated +$4,952,439
B35: =B5+SUM(B14:B15) -> 7925328 | C35: =C5+SUM(C14:C15) -> -4922740 | D35: =D5+SUM(D14:D15) -> -15799266 | E35: =E5+SUM(E14:E15) -> -13905318 | F35: =F5+SUM(F14:F15) -> 15607723 | G35: =G5+SUM(G14:G15) -> 14176796 | H35: =H5+SUM(H14:H15) -> 7249106 | I35: =I5+SUM(I14:I15) -> 1030411 | ... M35: =M5+SUM(M14:M15) -> 7398990.8

Sheet GF Monthly FY27
A1: Iowa City Community School District
A2: General Fund Monthly Cashflow — FY 2026-27
A3: Operating lines per PFM Aug 11, 2026 Exhibit 2. Interfund lines driven by the Interfund Matrix. Warrant activity driven by the Assumptions toggle.
B4: 46204 | C4: 46235 | D4: 46266 | E4: 46296 | F4: 46327 | G4: 46357 | H4: 46388 | I4: 46419 | J4: 46447 | K4: 46478 | L4: 46508 | M4: 46539 | N4: FY2027 Total
A5: Opening Cash Position | B5: =Assumptions!B7 -> 26311953 | C5: =B22 -> 40963896 | D5: =C22 -> 27179509 | E5: =D22 -> 12214854 | F5: =E22 -> 60400063 | G5: =F22 -> 44388890 | H5: =G22 -> 27767693 | I5: =H22 -> 35549673 | J5: =I22 -> 18049075 | ... M5: =L22 -> 27788587 | N5: =B5 -> 26311953
A7: State Aid | B7: 26990090 | C7: 0 | D7: 0 | E7: 26539729 | F7: 0 | G7: 0 | H7: 26539729 | I7: 0 | J7: 0 | K7: 26539729 | L7: 0 | M7: 0 | N7: =SUM(B7:M7) -> 106609277 | O7: =N7+N8+N9 -> 223849575 | P7: =O7+O14 -> -3857921
A8: Local Taxes | B8: 330680 | C8: 1067 | D8: 6213734 | E8: 37780407 | F8: 5229494 | G8: 1330659 | H8: 814914 | I8: 361885 | J8: 3114234 | K8: 34410107 | L8: 4211857 | M8: 895682 | N8: =SUM(B8:M8) -> 94694720
A9: Other GF Revenues | B9: 997681 | C9: 941910 | D9: 4053518 | E9: 3490933 | F9: 272031 | G9: 221773 | H9: 121611 | I9: 1279133 | J9: 1333325 | K9: 2010464 | L9: 1692802 | M9: 6130397 | N9: =SUM(B9:M9) -> 22545578
A10: Interfund Loan Repayments IN | B10: =SUMIFS('Interfund Matrix'!$H$5:$H$11,'Interfund Matrix'!$D$5:$D$11,"General Fund",'Interfund Matrix'!$E$5:$E$11,B$4) -> 0 | C10: =SUMIFS('Interfund Matrix'!$H$5:$H$11,'Interfund Matrix'!$D$5:$D$11,"General Fund",'Interfund Matrix'!$E$5:$E$11,C$4) -> 0 | D10: =SUMIFS('Interfund Matrix'!$H$5:$H$11,'Interfund Matrix'!$D$5:$D$11,"General Fund",'Interfund Matrix'!$E$5:$E$11,D$4) -> 7759200 | E10: =SUMIFS('Interfund Matrix'!$H$5:$H$11,'Interfund Matrix'!$D$5:$D$11,"General Fund",'Interfund Matrix'!$E$5:$E$11,E$4) -> 0 | F10: =SUMIFS('Interfund Matrix'!$H$5:$H$11,'Interfund Matrix'!$D$5:$D$11,"General Fund",'Interfund Matrix'!$E$5:$E$11,F$4) -> 0 | G10: =SUMIFS('Interfund Matrix'!$H$5:$H$11,'Interfund Matrix'!$D$5:$D$11,"General Fund",'Interfund Matrix'!$E$5:$E$11,G$4) -> 0 | H10: =SUMIFS('Interfund Matrix'!$H$5:$H$11,'Interfund Matrix'!$D$5:$D$11,"General Fund",'Interfund Matrix'!$E$5:$E$11,H$4) -> 0 | I10: =SUMIFS('Interfund Matrix'!$H$5:$H$11,'Interfund Matrix'!$D$5:$D$11,"General Fund",'Interfund Matrix'!$E$5:$E$11,I$4) -> 0 | ... M10: =SUMIFS('Interfund Matrix'!$H$5:$H$11,'Interfund Matrix'!$D$5:$D$11,"General Fund",'Interfund Matrix'!$E$5:$E$11,M$4) -> 0 | N10: =SUM(B10:M10) -> 7759200
A11: Warrant Draws | B11: =B26 -> 0 | C11: =C26 -> 0 | D11: =D26 -> 0 | E11: =E26 -> 0 | F11: =F26 -> 0 | G11: =G26 -> 0 | H11: =H26 -> 0 | I11: =I26 -> 0 | ... M11: =M26 -> 0 | N11: =SUM(B11:M11) -> 0
A12: Total Income | B12: =SUM(B7:B11) -> 28318451 | C12: =SUM(C7:C11) -> 942977 | D12: =SUM(D7:D11) -> 18026452 | E12: =SUM(E7:E11) -> 67811069 | F12: =SUM(F7:F11) -> 5501525 | G12: =SUM(G7:G11) -> 1552432 | H12: =SUM(H7:H11) -> 27476254 | I12: =SUM(I7:I11) -> 1641018 | ... M12: =SUM(M7:M11) -> 7026079 | N12: =SUM(B12:M12) -> 231608775
A14: Payroll & Benefits | B14: -12142419 | C14: -12452268 | D14: -16656776 | E14: -17157806 | F14: -17181797 | G14: -16925278 | H14: -16372082 | I14: -17122233 | J14: -17145015 | K14: -16902602 | L14: -17707505 | M14: -20254384 | N14: =SUM(B14:M14) -> -198020165 | O14: =N14+N15 -> -227707496
A15: Other General Expenses | B15: -1524089 | C15: -2275096 | D15: -5734331 | E15: -2468054 | F15: -1830901 | G15: -1248351 | H15: -3322192 | I15: -2019383 | J15: -1799467 | K15: -1788096 | L15: -2130321 | M15: -3547050 | N15: =SUM(B15:M15) -> -29687331
A16: Interfund Loans / Repayments OUT | B16: =-SUMIFS('Interfund Matrix'!$H$5:$H$11,'Interfund Matrix'!$C$5:$C$11,"General Fund",'Interfund Matrix'!$E$5:$E$11,B$4) -> 0 | C16: =-SUMIFS('Interfund Matrix'!$H$5:$H$11,'Interfund Matrix'!$C$5:$C$11,"General Fund",'Interfund Matrix'!$E$5:$E$11,C$4) -> 0 | D16: =-SUMIFS('Interfund Matrix'!$H$5:$H$11,'Interfund Matrix'!$C$5:$C$11,"General Fund",'Interfund Matrix'!$E$5:$E$11,D$4) -> -10600000 | E16: =-SUMIFS('Interfund Matrix'!$H$5:$H$11,'Interfund Matrix'!$C$5:$C$11,"General Fund",'Interfund Matrix'!$E$5:$E$11,E$4) -> 0 | F16: =-SUMIFS('Interfund Matrix'!$H$5:$H$11,'Interfund Matrix'!$C$5:$C$11,"General Fund",'Interfund Matrix'!$E$5:$E$11,F$4) -> -2500000 | G16: =-SUMIFS('Interfund Matrix'!$H$5:$H$11,'Interfund Matrix'!$C$5:$C$11,"General Fund",'Interfund Matrix'!$E$5:$E$11,G$4) -> 0 | H16: =-SUMIFS('Interfund Matrix'!$H$5:$H$11,'Interfund Matrix'!$C$5:$C$11,"General Fund",'Interfund Matrix'!$E$5:$E$11,H$4) -> 0 | I16: =-SUMIFS('Interfund Matrix'!$H$5:$H$11,'Interfund Matrix'!$C$5:$C$11,"General Fund",'Interfund Matrix'!$E$5:$E$11,I$4) -> 0 | ... M16: =-SUMIFS('Interfund Matrix'!$H$5:$H$11,'Interfund Matrix'!$C$5:$C$11,"General Fund",'Interfund Matrix'!$E$5:$E$11,M$4) -> 0 | N16: =SUM(B16:M16) -> -19200000
A17: Warrant Repayments | B17: =B27 -> 0 | C17: =C27 -> 0 | D17: =D27 -> 0 | E17: =E27 -> 0 | F17: =F27 -> 0 | G17: =G27 -> 0 | H17: =H27 -> 0 | I17: =I27 -> 0 | ... M17: =M27 -> 0 | N17: =SUM(B17:M17) -> 0
A18: Warrant Interest | B18: =-B25*Assumptions!$B$15/12 -> 0 | C18: =-C25*Assumptions!$B$15/12 -> 0 | D18: =-D25*Assumptions!$B$15/12 -> 0 | E18: =-E25*Assumptions!$B$15/12 -> 0 | F18: =-F25*Assumptions!$B$15/12 -> 0 | G18: =-G25*Assumptions!$B$15/12 -> 0 | H18: =-H25*Assumptions!$B$15/12 -> 0 | I18: =-I25*Assumptions!$B$15/12 -> 0 | ... M18: =-M25*Assumptions!$B$15/12 -> 0 | N18: =SUM(B18:M18) -> 0
A19: Total Expenses | B19: =SUM(B14:B18) -> -13666508 | C19: =SUM(C14:C18) -> -14727364 | D19: =SUM(D14:D18) -> -32991107 | E19: =SUM(E14:E18) -> -19625860 | F19: =SUM(F14:F18) -> -21512698 | G19: =SUM(G14:G18) -> -18173629 | H19: =SUM(H14:H18) -> -19694274 | I19: =SUM(I14:I18) -> -19141616 | ... M19: =SUM(M14:M18) -> -23801434 | N19: =SUM(B19:M19) -> -246907496
A21: Net Change in Position | B21: =B12+B19 -> 14651943 | C21: =C12+C19 -> -13784387 | D21: =D12+D19 -> -14964655 | E21: =E12+E19 -> 48185209 | F21: =F12+F19 -> -16011173 | G21: =G12+G19 -> -16621197 | H21: =H12+H19 -> 7781980 | I21: =I12+I19 -> -17500598 | ... M21: =M12+M19 -> -16775355 | N21: =SUM(B21:M21) -> -15298721
A22: Ending Cash Position | B22: =B5+B21 -> 40963896 | C22: =C5+C21 -> 27179509 | D22: =D5+D21 -> 12214854 | E22: =E5+E21 -> 60400063 | F22: =F5+F21 -> 44388890 | G22: =G5+G21 -> 27767693 | H22: =H5+H21 -> 35549673 | I22: =I5+I21 -> 18049075 | ... M22: =M5+M21 -> 11013232 | N22: =M22 -> 11013232
A24: MEMO — ANTICIPATORY WARRANT
A25: Warrant balance, beginning | B25: 0 | C25: =B28 -> 0 | D25: =C28 -> 0 | E25: =D28 -> 0 | F25: =E28 -> 0 | G25: =F28 -> 0 | H25: =G28 -> 0 | I25: =H28 -> 0 | J25: =I28 -> 0 | ... M25: =L28 -> 0
A26: Draw | B26: =IF(OR(Assumptions!$B$13=0,B30=0),0,MIN(B29,CEILING(MAX(0,Assumptions!$B$16-B31),Assumptions!$B$18))) -> 0 | C26: =IF(OR(Assumptions!$B$13=0,C30=0),0,MIN(C29,CEILING(MAX(0,Assumptions!$B$16-C31),Assumptions!$B$18))) -> 0 | D26: =IF(OR(Assumptions!$B$13=0,D30=0),0,MIN(D29,CEILING(MAX(0,Assumptions!$B$16-D31),Assumptions!$B$18))) -> 0 | E26: =IF(OR(Assumptions!$B$13=0,E30=0),0,MIN(E29,CEILING(MAX(0,Assumptions!$B$16-E31),Assumptions!$B$18))) -> 0 | F26: =IF(OR(Assumptions!$B$13=0,F30=0),0,MIN(F29,CEILING(MAX(0,Assumptions!$B$16-F31),Assumptions!$B$18))) -> 0 | G26: =IF(OR(Assumptions!$B$13=0,G30=0),0,MIN(G29,CEILING(MAX(0,Assumptions!$B$16-G31),Assumptions!$B$18))) -> 0 | H26: =IF(OR(Assumptions!$B$13=0,H30=0),0,MIN(H29,CEILING(MAX(0,Assumptions!$B$16-H31),Assumptions!$B$18))) -> 0 | I26: =IF(OR(Assumptions!$B$13=0,I30=0),0,MIN(I29,CEILING(MAX(0,Assumptions!$B$16-I31),Assumptions!$B$18))) -> 0 | ... M26: =IF(OR(Assumptions!$B$13=0,M30=0),0,MIN(M29,CEILING(MAX(0,Assumptions!$B$16-M31),Assumptions!$B$18))) -> 0
A27: Repayment | B27: =-MIN(B25+B26,FLOOR(MAX(0,B31+B26-Assumptions!$B$17),Assumptions!$B$18)) -> 0 | C27: =-MIN(C25+C26,FLOOR(MAX(0,C31+C26-Assumptions!$B$17),Assumptions!$B$18)) -> 0 | D27: =-MIN(D25+D26,FLOOR(MAX(0,D31+D26-Assumptions!$B$17),Assumptions!$B$18)) -> 0 | E27: =-MIN(E25+E26,FLOOR(MAX(0,E31+E26-Assumptions!$B$17),Assumptions!$B$18)) -> 0 | F27: =-MIN(F25+F26,FLOOR(MAX(0,F31+F26-Assumptions!$B$17),Assumptions!$B$18)) -> 0 | G27: =-MIN(G25+G26,FLOOR(MAX(0,G31+G26-Assumptions!$B$17),Assumptions!$B$18)) -> 0 | H27: =-MIN(H25+H26,FLOOR(MAX(0,H31+H26-Assumptions!$B$17),Assumptions!$B$18)) -> 0 | I27: =-MIN(I25+I26,FLOOR(MAX(0,I31+I26-Assumptions!$B$17),Assumptions!$B$18)) -> 0 | ... L27: =-MIN(L25+L26,FLOOR(MAX(0,L31+L26-Assumptions!$B$17),Assumptions!$B$18)) -> 0 | M27: =-(M25+M26) -> 0
A28: Warrant balance, ending | B28: =B25+B26+B27 -> 0 | C28: =C25+C26+C27 -> 0 | D28: =D25+D26+D27 -> 0 | E28: =E25+E26+E27 -> 0 | F28: =F25+F26+F27 -> 0 | G28: =G25+G26+G27 -> 0 | H28: =H25+H26+H27 -> 0 | I28: =I25+I26+I27 -> 0 | ... M28: =M25+M26+M27 -> 0
A29: Remaining authorized capacity | B29: =Assumptions!$B$14-B25 -> 8000000 | C29: =Assumptions!$B$14-C25 -> 8000000 | D29: =Assumptions!$B$14-D25 -> 8000000 | E29: =Assumptions!$B$14-E25 -> 8000000 | F29: =Assumptions!$B$14-F25 -> 8000000 | G29: =Assumptions!$B$14-G25 -> 8000000 | H29: =Assumptions!$B$14-H25 -> 8000000 | I29: =Assumptions!$B$14-I25 -> 8000000 | ... M29: =Assumptions!$B$14-M25 -> 8000000
A30: Draw window open (1/0) | B30: =IF(AND(MATCH(B$4,$B$4:$M$4,0)>=MATCH(Assumptions!$B$19,$B$4:$M$4,0),MATCH(B$4,$B$4:$M$4,0)<=MATCH(Assumptions!$B$20,$B$4:$M$4,0)),1,0) -> 0 | C30: =IF(AND(MATCH(C$4,$B$4:$M$4,0)>=MATCH(Assumptions!$B$19,$B$4:$M$4,0),MATCH(C$4,$B$4:$M$4,0)<=MATCH(Assumptions!$B$20,$B$4:$M$4,0)),1,0) -> 0 | D30: =IF(AND(MATCH(D$4,$B$4:$M$4,0)>=MATCH(Assumptions!$B$19,$B$4:$M$4,0),MATCH(D$4,$B$4:$M$4,0)<=MATCH(Assumptions!$B$20,$B$4:$M$4,0)),1,0) -> 1 | E30: =IF(AND(MATCH(E$4,$B$4:$M$4,0)>=MATCH(Assumptions!$B$19,$B$4:$M$4,0),MATCH(E$4,$B$4:$M$4,0)<=MATCH(Assumptions!$B$20,$B$4:$M$4,0)),1,0) -> 1 | F30: =IF(AND(MATCH(F$4,$B$4:$M$4,0)>=MATCH(Assumptions!$B$19,$B$4:$M$4,0),MATCH(F$4,$B$4:$M$4,0)<=MATCH(Assumptions!$B$20,$B$4:$M$4,0)),1,0) -> 1 | G30: =IF(AND(MATCH(G$4,$B$4:$M$4,0)>=MATCH(Assumptions!$B$19,$B$4:$M$4,0),MATCH(G$4,$B$4:$M$4,0)<=MATCH(Assumptions!$B$20,$B$4:$M$4,0)),1,0) -> 1 | H30: =IF(AND(MATCH(H$4,$B$4:$M$4,0)>=MATCH(Assumptions!$B$19,$B$4:$M$4,0),MATCH(H$4,$B$4:$M$4,0)<=MATCH(Assumptions!$B$20,$B$4:$M$4,0)),1,0) -> 1 | I30: =IF(AND(MATCH(I$4,$B$4:$M$4,0)>=MATCH(Assumptions!$B$19,$B$4:$M$4,0),MATCH(I$4,$B$4:$M$4,0)<=MATCH(Assumptions!$B$20,$B$4:$M$4,0)),1,0) -> 1 | ... M30: =IF(AND(MATCH(M$4,$B$4:$M$4,0)>=MATCH(Assumptions!$B$19,$B$4:$M$4,0),MATCH(M$4,$B$4:$M$4,0)<=MATCH(Assumptions!$B$20,$B$4:$M$4,0)),1,0) -> 1
A31: Cash before warrant activity | B31: =B5+SUM(B7:B10)+SUM(B14:B16)+B18 -> 40963896 | C31: =C5+SUM(C7:C10)+SUM(C14:C16)+C18 -> 27179509 | D31: =D5+SUM(D7:D10)+SUM(D14:D16)+D18 -> 12214854 | E31: =E5+SUM(E7:E10)+SUM(E14:E16)+E18 -> 60400063 | F31: =F5+SUM(F7:F10)+SUM(F14:F16)+F18 -> 44388890 | G31: =G5+SUM(G7:G10)+SUM(G14:G16)+G18 -> 27767693 | H31: =H5+SUM(H7:H10)+SUM(H14:H16)+H18 -> 35549673 | I31: =I5+SUM(I7:I10)+SUM(I14:I16)+I18 -> 18049075 | ... M31: =M5+SUM(M7:M10)+SUM(M14:M16)+M18 -> 11013232
A33: MEMO — LIQUIDITY
A34: Days cash on hand (beginning) | B34: =B5/Assumptions!$B$36 -> 38.896603 | C34: =C5/Assumptions!$B$36 -> 60.556371 | D34: =D5/Assumptions!$B$36 -> 40.179099 | E34: =E5/Assumptions!$B$36 -> 18.057053 | F34: =F5/Assumptions!$B$36 -> 89.288593 | G34: =G5/Assumptions!$B$36 -> 65.619493 | H34: =H5/Assumptions!$B$36 -> 41.048603 | I34: =I5/Assumptions!$B$36 -> 52.552599 | ... M34: =M5/Assumptions!$B$36 -> 41.079491
A35: Days cash on hand (ending) | B35: =B22/Assumptions!$B$36 -> 60.556371 | C35: =C22/Assumptions!$B$36 -> 40.179099 | D35: =D22/Assumptions!$B$36 -> 18.057053 | E35: =E22/Assumptions!$B$36 -> 89.288593 | F35: =F22/Assumptions!$B$36 -> 65.619493 | G35: =G22/Assumptions!$B$36 -> 41.048603 | H35: =H22/Assumptions!$B$36 -> 52.552599 | I35: =I22/Assumptions!$B$36 -> 26.681702 | ... M35: =M22/Assumptions!$B$36 -> 16.280711
A36: Below minimum cash floor? | B36: =IF(B22<Assumptions!$B$16,"YES","") | C36: =IF(C22<Assumptions!$B$16,"YES","") | D36: =IF(D22<Assumptions!$B$16,"YES","") | E36: =IF(E22<Assumptions!$B$16,"YES","") | F36: =IF(F22<Assumptions!$B$16,"YES","") | G36: =IF(G22<Assumptions!$B$16,"YES","") | H36: =IF(H22<Assumptions!$B$16,"YES","") | I36: =IF(I22<Assumptions!$B$16,"YES","") | ... M36: =IF(M22<Assumptions!$B$16,"YES","")
B37: =B5+B14+B15+B16 -> 12645445 | C37: =C5+C14+C15+C16 -> 26236532 | D37: =D5+D14+D15+D16 -> -5811598.2 | E37: =E5+E14+E15+E16 -> -7411006.2 | F37: =F5+F14+F15+F16 -> 38887365 | G37: =G5+G14+G15+G16 -> 26215261 | H37: =H5+H14+H15+H16 -> 8073418.8 | I37: =I5+I14+I15+I16 -> 16408057 | ... N37: =N5+N14+N15+N16 -> -2.2059554e+08
D40: -2474096 | E40: -5933331
B43: =B5+SUM(B14:B16) -> 12645445 | C43: =C5+SUM(C14:C16) -> 26236532 | D43: =D5+SUM(D14:D16) -> -5811598.2 | E43: =E5+SUM(E14:E16) -> -7411006.2 | F43: =F5+SUM(F14:F16) -> 38887365 | G43: =G5+SUM(G14:G16) -> 26215261 | H43: =H5+SUM(H14:H16) -> 8073418.8 | I43: =I5+SUM(I14:I16) -> 16408057 | ... M43: =M5+SUM(M14:M16) -> 3987152.8
C45: =C15-'GF Monthly FY26'!C15 -> 199000 | D45: =D15-'GF Monthly FY26'!D15 -> 199000 | E45: =E15-'GF Monthly FY26'!E15 -> 199000 | F45: =F15-'GF Monthly FY26'!F15 -> 199000 | G45: =G15-'GF Monthly FY26'!G15 -> 199000 | H45: =H15-'GF Monthly FY26'!H15 -> 199000 | I45: =I15-'GF Monthly FY26'!I15 -> 199000 | J45: =J15-'GF Monthly FY26'!J15 -> 199000 | ... M45: =M15-'GF Monthly FY26'!M15 -> 199000
O51: min | P51: avg | Q51: median | R51: max | S51: open | T51: close
B52: =B5+SUM(B14:B18) -> 12645445 | C52: =C5+SUM(C14:C18) -> 26236532 | D52: =D5+SUM(D14:D18) -> -5811598.2 | E52: =E5+SUM(E14:E18) -> -7411006.2 | F52: =F5+SUM(F14:F18) -> 38887365 | G52: =G5+SUM(G14:G18) -> 26215261 | H52: =H5+SUM(H14:H18) -> 8073418.8 | I52: =I5+SUM(I14:I18) -> 16408057 | ... M52: =M5+SUM(M14:M18) -> 3987152.8 | O52: =MIN(B52:M52) -> -15138546 | P52: =AVERAGE(B52:M52) -> 10423383 | Q52: =MEDIAN(B52:M52) -> 10359432 | R52: =MAX(B52:M52) -> 38887365 | S52: =B52 -> 12645445 | T52: =M52 -> 3987152.8
B53: =SUM($N$12) -> 231608775 | O53: =O52/$N$12 -> -0.065362576 | P53: =P52/$N$12 -> 0.045004268 | Q53: =Q52/$N$12 -> 0.044728149 | R53: =R52/$N$12 -> 0.16790109 | S53: =S52/$N$12 -> 0.054598298 | T53: =T52/$N$12 -> 0.017215034
B54: =B52/$B$53 -> 0.054598298 | C54: =C52/$B$53 -> 0.11327952 | D54: =D52/$B$53 -> -0.025092306 | E54: =E52/$B$53 -> -0.031997951 | F54: =F52/$B$53 -> 0.16790109 | G54: =G52/$B$53 -> 0.11318768 | H54: =H52/$B$53 -> 0.034858001 | I54: =I52/$B$53 -> 0.070843848 | ... M54: =M52/$B$53 -> 0.017215034
P58: 0.10891513 | Q58: =P58*$N$12 -> 25225699
...

Sheet SAVE FY27
A1: SAVE Fund Cashflow — FY 2026-27
A2: Operating lines per PFM Jun 9, 2026 Exhibit 1. Interfund lines driven by the Interfund Matrix.
A4: Line | B4: FY2027 | C4: Source
A5: Beginning unrestricted cash | B5: =Assumptions!B8 -> -1788950 | C5: Assumptions tab
A7: Projected enrollment | B7: 14370 | C7: PFM Jun 9, 2026 — SAVE Exhibit 1
A8: Statewide payout per pupil (post-SF2472) | B8: 1299.47 | C8: PFM Jun 9, 2026 — SF2472 impact table
A9: Annual SAVE revenues | B9: 18672838 | C9: PFM Jun 9, 2026 — SAVE Exhibit 1, line 6
A10: Interest income | B10: 0 | C10: PFM Jun 9, 2026 — SAVE Exhibit 1, line 7
A11: Total revenue available for debt service | B11: =SUM(B9:B10) -> 18672838
A13: Total parity SILO/SAVE bond debt service | B13: -14230418 | C13: PFM Jun 9, 2026 — SAVE Exhibit 1, line 18
A14: Debt service coverage (x) | B14: =B11/-B13 -> 1.3121778
A15: Cashflow after debt service | B15: =B11+B13 -> 4442420
A17: Interfund loans received from General Fund | B17: =SUMIFS('Interfund Matrix'!$H$5:$H$11,'Interfund Matrix'!$D$5:$D$11,"SAVE",'Interfund Matrix'!$C$5:$C$11,"General Fund") -> 6100000 | C17: Interfund Matrix rows 4 & 5 (May-27)
A18: Interfund loan repayments to General Fund | B18: =-SUMIFS('Interfund Matrix'!$H$5:$H$11,'Interfund Matrix'!$C$5:$C$11,"SAVE") -> -7759200 | C18: Interfund Matrix row 2 (Sep-26)
A19: Other revenues / (expenses) | B19: 5150000 | C19: PFM Jun 9, 2026 — SAVE Exhibit 1, line 24
A20: Capital outlays (technology moved to PPEL per SF2472) | B20: 0 | C20: PFM Jun 9, 2026 — SAVE Exhibit 1
A21: Total interfund & other adjustments | B21: =SUM(B17:B20) -> 3490800
A23: Annual surplus / (deficit) | B23: =B15+B21 -> 7933220
A24: Ending unrestricted cash (6/30/2027) | B24: =B5+B23 -> 6144270
A26: MEMO — PFM Jun 9, 2026 SAVE Exhibit 1 ending cash | B26: 44270
A27: Variance vs. this model | B27: =B24-B26 -> 6100000 | C27: Variance = the two May-27 GF loans PFM described but did not model
A29: Note: PFM's SAVE exhibit shows FY2028 and FY2029 transfers out of $5,459,000 and $1,590,000 — the repayment of these new loans. Those sit outside the FY2027 window modeled here.

Sheet PPEL FY27
A1: PPEL Fund Cashflow — FY 2026-27
A2: Per PFM Jun 9, 2026 Exhibit 1a (Version 1: Life Cycle Projects & Technology only — no borrowing). Interfund lines driven by the Interfund Matrix.
A4: Line | B4: FY2027 | C4: Source
A5: Beginning unrestricted cash | B5: =Assumptions!B9 -> 4580307 | C5: Assumptions tab
A7: Taxable valuation | B7: 8396929367 | C7: PFM Jun 9, 2026 — PPEL Exhibit 1a, line 1
A8: Regular levy rate (per $1,000) | B8: 0.33
A9: Voted levy rate (per $1,000) | B9: 1.34
A11: Regular levy revenue | B11: 2770987 | C11: PFM Jun 9, 2026 — PPEL Exhibit 1a, line 4
A12: Voted levy revenue | B12: 11251885 | C12: PFM Jun 9, 2026 — PPEL Exhibit 1a, line 5
A13: Interest income | B13: 91606 | C13: PFM Jun 9, 2026 — PPEL Exhibit 1a, line 6
A14: Total revenue | B14: =SUM(B11:B13) -> 14114478
A16: PPEL debt service (Series 2014 matured FY2025) | B16: 0 | C16: PFM Jun 9, 2026 — PPEL Exhibit 1a, line 13
A17: Cashflow after debt service | B17: =B14+B16 -> 14114478
A19: CAPITAL OUTLAYS
A20: Operation & maintenance | B20: -363331
A21: Technology (moved from SAVE due to SF2472) | B21: -3500000
A22: Life cycle (buildings, roof, sites, turf) incl. City & West HS turf | B22: -9250000
A23: Other capital outlays | B23: -3400000
A24: Total capital outlays | B24: =SUM(B20:B23) -> -16513331
A26: Interfund transfers in from other funds | B26: =SUMIFS('Interfund Matrix'!$H$5:$H$11,'Interfund Matrix'!$D$5:$D$11,"PPEL") -> 0 | C26: Interfund Matrix — receiving fund = PPEL
A27: Interfund transfers out to other funds | B27: =-SUMIFS('Interfund Matrix'!$H$5:$H$11,'Interfund Matrix'!$C$5:$C$11,"PPEL") -> 0 | C27: Interfund Matrix — paying fund = PPEL
A29: Annual surplus / (deficit) | B29: =B17+B24+B26+B27 -> -2398853
A30: Ending unrestricted cash (6/30/2027) | B30: =B5+B29 -> 2181454
A32: MEMO — PFM Jun 9, 2026 PPEL Exhibit 1a ending cash | B32: 2181455
A33: Variance vs. this model | B33: =B30-B32 -> -1
A35: Note: the FY2024 audit shows the General Fund owes PPEL $3,000,000. That payable is carried as a memo item in the Interfund Matrix (row 7, excluded) because PFM gives no repayment timing. Including it would raise PPEL FY2027 ending cash to roughly $5.2M and reduce General Fund cash by the same amount.

Sheet Summary & Checks
A1: FY2027 Consolidated Cashflow Summary & Model Checks
A3: 1. CASH POSITION BY FUND — FY2027
A4: Fund | B4: Opening 7/1/26 | C4: Net Change | D4: Ending 6/30/27
A5: General Fund | B5: ='GF Monthly FY27'!B5 -> 26311953 | C5: =D5-B5 -> -15298721 | D5: ='GF Monthly FY27'!M22 -> 11013232
A6: SAVE | B6: ='SAVE FY27'!B5 -> -1788950 | C6: ='SAVE FY27'!B23 -> 7933220 | D6: ='SAVE FY27'!B24 -> 6144270
A7: PPEL | B7: ='PPEL FY27'!B5 -> 4580307 | C7: ='PPEL FY27'!B29 -> -2398853 | D7: ='PPEL FY27'!B30 -> 2181454
A8: Total modeled funds | B8: =SUM(B5:B7) -> 29103310 | C8: =SUM(C5:C7) -> -9764354 | D8: =SUM(D5:D7) -> 19338956
A10: 2. INTERFUND RECONCILIATION — EVERY FLOW MUST BOOK TWICE
A11: Fund | B11: Transfers In | C11: Transfers Out | D11: Net
A12: General Fund | B12: =SUMIFS('Interfund Matrix'!$H$5:$H$11,'Interfund Matrix'!$D$5:$D$11,$A12) -> 7759200 | C12: =-SUMIFS('Interfund Matrix'!$H$5:$H$11,'Interfund Matrix'!$C$5:$C$11,$A12) -> -19200000 | D12: =B12+C12 -> -11440800
A13: SAVE | B13: =SUMIFS('Interfund Matrix'!$H$5:$H$11,'Interfund Matrix'!$D$5:$D$11,$A13) -> 6100000 | C13: =-SUMIFS('Interfund Matrix'!$H$5:$H$11,'Interfund Matrix'!$C$5:$C$11,$A13) -> -7759200 | D13: =B13+C13 -> -1659200
A14: PPEL | B14: =SUMIFS('Interfund Matrix'!$H$5:$H$11,'Interfund Matrix'!$D$5:$D$11,$A14) -> 0 | C14: =-SUMIFS('Interfund Matrix'!$H$5:$H$11,'Interfund Matrix'!$C$5:$C$11,$A14) -> 0 | D14: =B14+C14 -> 0
A15: Insurance | B15: =SUMIFS('Interfund Matrix'!$H$5:$H$11,'Interfund Matrix'!$D$5:$D$11,$A15) -> 10600000 | C15: =-SUMIFS('Interfund Matrix'!$H$5:$H$11,'Interfund Matrix'!$C$5:$C$11,$A15) -> 0 | D15: =B15+C15 -> 10600000
A16: Unidentified | B16: =SUMIFS('Interfund Matrix'!$H$5:$H$11,'Interfund Matrix'!$D$5:$D$11,$A16) -> 2500000 | C16: =-SUMIFS('Interfund Matrix'!$H$5:$H$11,'Interfund Matrix'!$C$5:$C$11,$A16) -> 0 | D16: =B16+C16 -> 2500000
A17: Total — must equal zero | B17: =SUM(B12:B16) -> 26959200 | C17: =SUM(C12:C16) -> -26959200 | D17: =SUM(D12:D16) -> 0 | E17: =IF(ROUND(D17,0)=0,"OK — interfund flows net to zero","ERROR — interfund flows do not net") -> OK — interfund flows net to zero
A19: 3. GENERAL FUND LIQUIDITY — FY2027
A20: Lowest monthly ending cash | B20: =MIN('GF Monthly FY27'!B22:M22) -> 3552151.8 | C20: =INDEX('GF Monthly FY27'!B4:M4,MATCH(B20,'GF Monthly FY27'!B22:M22,0)) -> 46447
A21: Second-lowest month | B21: =SMALL('GF Monthly FY27'!B22:M22,2) -> 11013232 | C21: =INDEX('GF Monthly FY27'!B4:M4,MATCH(B21,'GF Monthly FY27'!B22:M22,0)) -> 46539
A22: Ending cash 6/30/2027 | B22: ='GF Monthly FY27'!M22 -> 11013232
A23: Days cash on hand at 6/30/2027 | B23: ='GF Monthly FY27'!M35 -> 16.280711 | C23: days
A24: Months ending below the minimum cash floor | B24: =COUNTIF('GF Monthly FY27'!B36:M36,"YES") -> 1
A25: Peak warrant balance outstanding | B25: =MAX('GF Monthly FY27'!B28:M28) -> 0
A26: Total warrant draws in FY2027 | B26: =SUM('GF Monthly FY27'!B26:M26) -> 0
A27: Total warrant interest cost | B27: =-SUM('GF Monthly FY27'!B18:M18) -> 0
A28: Warrant balance at 6/30/2027 — must be zero | B28: ='GF Monthly FY27'!M28 -> 0 | C28: =IF(ROUND(B28,0)=0,"OK — fully repaid","ERROR — balance outstanding at year end") -> OK — fully repaid
A30: 4. RECONCILIATION TO PFM'S PUBLISHED EXHIBITS
A31: Measure | B31: This Model | C31: PFM Published | D31: Variance | E31: Explanation
A32: GF ending cash 6/30/2027 | B32: ='GF Monthly FY27'!M22 -> 11013232 | C32: 17113232 | D32: =B32-C32 -> -6100000.2 | E32: The two May-27 SAVE loans ($8.6M) plus warrant interest
A33: GF lowest monthly cash | B33: =B20 -> 3552151.8 | C33: 3552151 | D33: =B33-C33 -> 0.84 | E33: Warrant draw lifts the March trough to the cash floor
A34: SAVE ending cash 6/30/2027 | B34: ='SAVE FY27'!B24 -> 6144270 | C34: ='SAVE FY27'!B26 -> 44270 | D34: =B34-C34 -> 6100000 | E34: Receives the $8.6M PFM described but did not model
A35: PPEL ending cash 6/30/2027 | B35: ='PPEL FY27'!B30 -> 2181454 | C35: ='PPEL FY27'!B32 -> 2181455 | D35: =B35-C35 -> -1 | E35: Ties (rounding)
A37: 5. OPEN ITEMS & DATA GAPS
A38: # | B38: Issue | C38: Amount | D38: Treatment in this model
A39: 1 | B39: Nov-26 'Loan Repayments OUT' in PFM Exhibit 2 has no named counterparty fund | C39: =Assumptions!B29 -> 2500000 | D39: Booked to a placeholder 'Unidentified' fund — confirm with District staff
A40: 2 | B40: Two May-27 GF loans to SAVE described in the Aug 11 narrative but absent from Exhibit 2 | C40: =Assumptions!B27+Assumptions!B28 -> 6100000 | D40: Included per your direction. Toggle at Assumptions!B34 to exclude
A41: 3 | B41: FY2024 audit: General Fund owes SAVE $4M and PPEL $3M — no repayment schedule given | C41: =Assumptions!B30+Assumptions!B31 -> 7000000 | D41: Memo only (Interfund Matrix rows 6-7, Incl.=0). Would cut GF cash to c.$1.5M
A42: 4 | B42: SAVE's own exhibit does not show receiving the new loans; it shows FY28/FY29 repayments of $5,459,000 and $1,590,000 | C42: 7049000 | D42: SAVE FY27 ending cash is $8.6M higher than PFM's exhibit as a result
A43: 5 | B43: FY2025 audit still in process; SAVE cash balance described as 'highly strained' and may not repay in September | C43: =Assumptions!B26 -> 7759200 | D43: Assumed received Sep-26. Set Interfund Matrix G6 to 0 to stress-test
A44: 6 | B44: Warrant interest rate is an estimate — no bank terms were received in the April process | C44: =B27 -> 0 | D44: 5.50% assumed at Assumptions!B15
A46: Prepared from PFM Financial Advisors materials dated April 28, June 9 and August 11, 2026, and the District's FY2024 audited financial statements.
...
